{
 "cells": [
  {
   "cell_type": "code",
   "execution_count": null,
   "metadata": {
    "colab": {
     "base_uri": "https://localhost:8080/",
     "height": 1000
    },
    "id": "I2fEzMSQkSLv",
    "outputId": "208f6412-8574-4737-e1dd-7032477c5384"
   },
   "outputs": [
    {
     "name": "stdout",
     "output_type": "stream",
     "text": [
      "Epoch 1/30\n"
     ]
    },
    {
     "name": "stderr",
     "output_type": "stream",
     "text": [
      "/usr/local/lib/python3.10/dist-packages/keras/src/trainers/data_adapters/py_dataset_adapter.py:121: UserWarning: Your `PyDataset` class should call `super().__init__(**kwargs)` in its constructor. `**kwargs` can include `workers`, `use_multiprocessing`, `max_queue_size`. Do not pass these arguments to `fit()`, as they will be ignored.\n",
      "  self._warn_if_super_not_called()\n"
     ]
    },
    {
     "ename": "InvalidArgumentError",
     "evalue": "Graph execution error:\n\nDetected at node UnsortedSegmentSum_1 defined at (most recent call last):\n  File \"/usr/lib/python3.10/runpy.py\", line 196, in _run_module_as_main\n\n  File \"/usr/lib/python3.10/runpy.py\", line 86, in _run_code\n\n  File \"/usr/local/lib/python3.10/dist-packages/colab_kernel_launcher.py\", line 37, in <module>\n\n  File \"/usr/local/lib/python3.10/dist-packages/traitlets/config/application.py\", line 992, in launch_instance\n\n  File \"/usr/local/lib/python3.10/dist-packages/ipykernel/kernelapp.py\", line 619, in start\n\n  File \"/usr/local/lib/python3.10/dist-packages/tornado/platform/asyncio.py\", line 195, in start\n\n  File \"/usr/lib/python3.10/asyncio/base_events.py\", line 603, in run_forever\n\n  File \"/usr/lib/python3.10/asyncio/base_events.py\", line 1909, in _run_once\n\n  File \"/usr/lib/python3.10/asyncio/events.py\", line 80, in _run\n\n  File \"/usr/local/lib/python3.10/dist-packages/tornado/ioloop.py\", line 685, in <lambda>\n\n  File \"/usr/local/lib/python3.10/dist-packages/tornado/ioloop.py\", line 738, in _run_callback\n\n  File \"/usr/local/lib/python3.10/dist-packages/tornado/gen.py\", line 825, in inner\n\n  File \"/usr/local/lib/python3.10/dist-packages/tornado/gen.py\", line 786, in run\n\n  File \"/usr/local/lib/python3.10/dist-packages/ipykernel/kernelbase.py\", line 361, in process_one\n\n  File \"/usr/local/lib/python3.10/dist-packages/tornado/gen.py\", line 234, in wrapper\n\n  File \"/usr/local/lib/python3.10/dist-packages/ipykernel/kernelbase.py\", line 261, in dispatch_shell\n\n  File \"/usr/local/lib/python3.10/dist-packages/tornado/gen.py\", line 234, in wrapper\n\n  File \"/usr/local/lib/python3.10/dist-packages/ipykernel/kernelbase.py\", line 539, in execute_request\n\n  File \"/usr/local/lib/python3.10/dist-packages/tornado/gen.py\", line 234, in wrapper\n\n  File \"/usr/local/lib/python3.10/dist-packages/ipykernel/ipkernel.py\", line 302, in do_execute\n\n  File \"/usr/local/lib/python3.10/dist-packages/ipykernel/zmqshell.py\", line 539, in run_cell\n\n  File \"/usr/local/lib/python3.10/dist-packages/IPython/core/interactiveshell.py\", line 2975, in run_cell\n\n  File \"/usr/local/lib/python3.10/dist-packages/IPython/core/interactiveshell.py\", line 3030, in _run_cell\n\n  File \"/usr/local/lib/python3.10/dist-packages/IPython/core/async_helpers.py\", line 78, in _pseudo_sync_runner\n\n  File \"/usr/local/lib/python3.10/dist-packages/IPython/core/interactiveshell.py\", line 3257, in run_cell_async\n\n  File \"/usr/local/lib/python3.10/dist-packages/IPython/core/interactiveshell.py\", line 3473, in run_ast_nodes\n\n  File \"/usr/local/lib/python3.10/dist-packages/IPython/core/interactiveshell.py\", line 3553, in run_code\n\n  File \"<ipython-input-17-892f160e7e0d>\", line 3, in <cell line: 3>\n\n  File \"/usr/local/lib/python3.10/dist-packages/keras/src/utils/traceback_utils.py\", line 117, in error_handler\n\n  File \"/usr/local/lib/python3.10/dist-packages/keras/src/backend/tensorflow/trainer.py\", line 318, in fit\n\n  File \"/usr/local/lib/python3.10/dist-packages/keras/src/backend/tensorflow/trainer.py\", line 121, in one_step_on_iterator\n\n  File \"/usr/local/lib/python3.10/dist-packages/keras/src/backend/tensorflow/trainer.py\", line 108, in one_step_on_data\n\n  File \"/usr/local/lib/python3.10/dist-packages/keras/src/backend/tensorflow/trainer.py\", line 77, in train_step\n\n  File \"/usr/local/lib/python3.10/dist-packages/keras/src/trainers/trainer.py\", line 444, in compute_metrics\n\n  File \"/usr/local/lib/python3.10/dist-packages/keras/src/trainers/compile_utils.py\", line 330, in update_state\n\n  File \"/usr/local/lib/python3.10/dist-packages/keras/src/trainers/compile_utils.py\", line 17, in update_state\n\n  File \"/usr/local/lib/python3.10/dist-packages/keras/src/metrics/confusion_metrics.py\", line 1376, in update_state\n\n  File \"/usr/local/lib/python3.10/dist-packages/keras/src/metrics/metrics_utils.py\", line 481, in update_confusion_matrix_variables\n\n  File \"/usr/local/lib/python3.10/dist-packages/keras/src/metrics/metrics_utils.py\", line 277, in _update_confusion_matrix_variables_optimized\n\n  File \"/usr/local/lib/python3.10/dist-packages/keras/src/ops/math.py\", line 59, in segment_sum\n\n  File \"/usr/local/lib/python3.10/dist-packages/keras/src/backend/tensorflow/math.py\", line 17, in segment_sum\n\ndata.shape = [32] does not start with segment_ids.shape = [224]\n\t [[{{node UnsortedSegmentSum_1}}]] [Op:__inference_one_step_on_iterator_16725]",
     "output_type": "error",
     "traceback": [
      "\u001b[0;31m---------------------------------------------------------------------------\u001b[0m",
      "\u001b[0;31mInvalidArgumentError\u001b[0m                      Traceback (most recent call last)",
      "\u001b[0;32m<ipython-input-17-892f160e7e0d>\u001b[0m in \u001b[0;36m<cell line: 3>\u001b[0;34m()\u001b[0m\n\u001b[1;32m      1\u001b[0m \u001b[0;31m# Step 5: Train the Model with Early Stopping\u001b[0m\u001b[0;34m\u001b[0m\u001b[0;34m\u001b[0m\u001b[0m\n\u001b[1;32m      2\u001b[0m \u001b[0mearly_stopping\u001b[0m \u001b[0;34m=\u001b[0m \u001b[0mEarlyStopping\u001b[0m\u001b[0;34m(\u001b[0m\u001b[0mmonitor\u001b[0m\u001b[0;34m=\u001b[0m\u001b[0;34m'val_loss'\u001b[0m\u001b[0;34m,\u001b[0m \u001b[0mpatience\u001b[0m\u001b[0;34m=\u001b[0m\u001b[0;36m5\u001b[0m\u001b[0;34m,\u001b[0m \u001b[0mrestore_best_weights\u001b[0m\u001b[0;34m=\u001b[0m\u001b[0;32mTrue\u001b[0m\u001b[0;34m)\u001b[0m\u001b[0;34m\u001b[0m\u001b[0;34m\u001b[0m\u001b[0m\n\u001b[0;32m----> 3\u001b[0;31m \u001b[0mhistory\u001b[0m \u001b[0;34m=\u001b[0m \u001b[0mmodel\u001b[0m\u001b[0;34m.\u001b[0m\u001b[0mfit\u001b[0m\u001b[0;34m(\u001b[0m\u001b[0mtrain_gen\u001b[0m\u001b[0;34m,\u001b[0m \u001b[0mvalidation_data\u001b[0m\u001b[0;34m=\u001b[0m\u001b[0;34m(\u001b[0m\u001b[0mX_test\u001b[0m\u001b[0;34m,\u001b[0m \u001b[0my_test\u001b[0m\u001b[0;34m)\u001b[0m\u001b[0;34m,\u001b[0m \u001b[0mepochs\u001b[0m\u001b[0;34m=\u001b[0m\u001b[0;36m30\u001b[0m\u001b[0;34m,\u001b[0m \u001b[0mcallbacks\u001b[0m\u001b[0;34m=\u001b[0m\u001b[0;34m[\u001b[0m\u001b[0mearly_stopping\u001b[0m\u001b[0;34m]\u001b[0m\u001b[0;34m)\u001b[0m\u001b[0;34m\u001b[0m\u001b[0;34m\u001b[0m\u001b[0m\n\u001b[0m",
      "\u001b[0;32m/usr/local/lib/python3.10/dist-packages/keras/src/utils/traceback_utils.py\u001b[0m in \u001b[0;36merror_handler\u001b[0;34m(*args, **kwargs)\u001b[0m\n\u001b[1;32m    120\u001b[0m             \u001b[0;31m# To get the full stack trace, call:\u001b[0m\u001b[0;34m\u001b[0m\u001b[0;34m\u001b[0m\u001b[0m\n\u001b[1;32m    121\u001b[0m             \u001b[0;31m# `keras.config.disable_traceback_filtering()`\u001b[0m\u001b[0;34m\u001b[0m\u001b[0;34m\u001b[0m\u001b[0m\n\u001b[0;32m--> 122\u001b[0;31m             \u001b[0;32mraise\u001b[0m \u001b[0me\u001b[0m\u001b[0;34m.\u001b[0m\u001b[0mwith_traceback\u001b[0m\u001b[0;34m(\u001b[0m\u001b[0mfiltered_tb\u001b[0m\u001b[0;34m)\u001b[0m \u001b[0;32mfrom\u001b[0m \u001b[0;32mNone\u001b[0m\u001b[0;34m\u001b[0m\u001b[0;34m\u001b[0m\u001b[0m\n\u001b[0m\u001b[1;32m    123\u001b[0m         \u001b[0;32mfinally\u001b[0m\u001b[0;34m:\u001b[0m\u001b[0;34m\u001b[0m\u001b[0;34m\u001b[0m\u001b[0m\n\u001b[1;32m    124\u001b[0m             \u001b[0;32mdel\u001b[0m \u001b[0mfiltered_tb\u001b[0m\u001b[0;34m\u001b[0m\u001b[0;34m\u001b[0m\u001b[0m\n",
      "\u001b[0;32m/usr/local/lib/python3.10/dist-packages/tensorflow/python/eager/execute.py\u001b[0m in \u001b[0;36mquick_execute\u001b[0;34m(op_name, num_outputs, inputs, attrs, ctx, name)\u001b[0m\n\u001b[1;32m     51\u001b[0m   \u001b[0;32mtry\u001b[0m\u001b[0;34m:\u001b[0m\u001b[0;34m\u001b[0m\u001b[0;34m\u001b[0m\u001b[0m\n\u001b[1;32m     52\u001b[0m     \u001b[0mctx\u001b[0m\u001b[0;34m.\u001b[0m\u001b[0mensure_initialized\u001b[0m\u001b[0;34m(\u001b[0m\u001b[0;34m)\u001b[0m\u001b[0;34m\u001b[0m\u001b[0;34m\u001b[0m\u001b[0m\n\u001b[0;32m---> 53\u001b[0;31m     tensors = pywrap_tfe.TFE_Py_Execute(ctx._handle, device_name, op_name,\n\u001b[0m\u001b[1;32m     54\u001b[0m                                         inputs, attrs, num_outputs)\n\u001b[1;32m     55\u001b[0m   \u001b[0;32mexcept\u001b[0m \u001b[0mcore\u001b[0m\u001b[0;34m.\u001b[0m\u001b[0m_NotOkStatusException\u001b[0m \u001b[0;32mas\u001b[0m \u001b[0me\u001b[0m\u001b[0;34m:\u001b[0m\u001b[0;34m\u001b[0m\u001b[0;34m\u001b[0m\u001b[0m\n",
      "\u001b[0;31mInvalidArgumentError\u001b[0m: Graph execution error:\n\nDetected at node UnsortedSegmentSum_1 defined at (most recent call last):\n  File \"/usr/lib/python3.10/runpy.py\", line 196, in _run_module_as_main\n\n  File \"/usr/lib/python3.10/runpy.py\", line 86, in _run_code\n\n  File \"/usr/local/lib/python3.10/dist-packages/colab_kernel_launcher.py\", line 37, in <module>\n\n  File \"/usr/local/lib/python3.10/dist-packages/traitlets/config/application.py\", line 992, in launch_instance\n\n  File \"/usr/local/lib/python3.10/dist-packages/ipykernel/kernelapp.py\", line 619, in start\n\n  File \"/usr/local/lib/python3.10/dist-packages/tornado/platform/asyncio.py\", line 195, in start\n\n  File \"/usr/lib/python3.10/asyncio/base_events.py\", line 603, in run_forever\n\n  File \"/usr/lib/python3.10/asyncio/base_events.py\", line 1909, in _run_once\n\n  File \"/usr/lib/python3.10/asyncio/events.py\", line 80, in _run\n\n  File \"/usr/local/lib/python3.10/dist-packages/tornado/ioloop.py\", line 685, in <lambda>\n\n  File \"/usr/local/lib/python3.10/dist-packages/tornado/ioloop.py\", line 738, in _run_callback\n\n  File \"/usr/local/lib/python3.10/dist-packages/tornado/gen.py\", line 825, in inner\n\n  File \"/usr/local/lib/python3.10/dist-packages/tornado/gen.py\", line 786, in run\n\n  File \"/usr/local/lib/python3.10/dist-packages/ipykernel/kernelbase.py\", line 361, in process_one\n\n  File \"/usr/local/lib/python3.10/dist-packages/tornado/gen.py\", line 234, in wrapper\n\n  File \"/usr/local/lib/python3.10/dist-packages/ipykernel/kernelbase.py\", line 261, in dispatch_shell\n\n  File \"/usr/local/lib/python3.10/dist-packages/tornado/gen.py\", line 234, in wrapper\n\n  File \"/usr/local/lib/python3.10/dist-packages/ipykernel/kernelbase.py\", line 539, in execute_request\n\n  File \"/usr/local/lib/python3.10/dist-packages/tornado/gen.py\", line 234, in wrapper\n\n  File \"/usr/local/lib/python3.10/dist-packages/ipykernel/ipkernel.py\", line 302, in do_execute\n\n  File \"/usr/local/lib/python3.10/dist-packages/ipykernel/zmqshell.py\", line 539, in run_cell\n\n  File \"/usr/local/lib/python3.10/dist-packages/IPython/core/interactiveshell.py\", line 2975, in run_cell\n\n  File \"/usr/local/lib/python3.10/dist-packages/IPython/core/interactiveshell.py\", line 3030, in _run_cell\n\n  File \"/usr/local/lib/python3.10/dist-packages/IPython/core/async_helpers.py\", line 78, in _pseudo_sync_runner\n\n  File \"/usr/local/lib/python3.10/dist-packages/IPython/core/interactiveshell.py\", line 3257, in run_cell_async\n\n  File \"/usr/local/lib/python3.10/dist-packages/IPython/core/interactiveshell.py\", line 3473, in run_ast_nodes\n\n  File \"/usr/local/lib/python3.10/dist-packages/IPython/core/interactiveshell.py\", line 3553, in run_code\n\n  File \"<ipython-input-17-892f160e7e0d>\", line 3, in <cell line: 3>\n\n  File \"/usr/local/lib/python3.10/dist-packages/keras/src/utils/traceback_utils.py\", line 117, in error_handler\n\n  File \"/usr/local/lib/python3.10/dist-packages/keras/src/backend/tensorflow/trainer.py\", line 318, in fit\n\n  File \"/usr/local/lib/python3.10/dist-packages/keras/src/backend/tensorflow/trainer.py\", line 121, in one_step_on_iterator\n\n  File \"/usr/local/lib/python3.10/dist-packages/keras/src/backend/tensorflow/trainer.py\", line 108, in one_step_on_data\n\n  File \"/usr/local/lib/python3.10/dist-packages/keras/src/backend/tensorflow/trainer.py\", line 77, in train_step\n\n  File \"/usr/local/lib/python3.10/dist-packages/keras/src/trainers/trainer.py\", line 444, in compute_metrics\n\n  File \"/usr/local/lib/python3.10/dist-packages/keras/src/trainers/compile_utils.py\", line 330, in update_state\n\n  File \"/usr/local/lib/python3.10/dist-packages/keras/src/trainers/compile_utils.py\", line 17, in update_state\n\n  File \"/usr/local/lib/python3.10/dist-packages/keras/src/metrics/confusion_metrics.py\", line 1376, in update_state\n\n  File \"/usr/local/lib/python3.10/dist-packages/keras/src/metrics/metrics_utils.py\", line 481, in update_confusion_matrix_variables\n\n  File \"/usr/local/lib/python3.10/dist-packages/keras/src/metrics/metrics_utils.py\", line 277, in _update_confusion_matrix_variables_optimized\n\n  File \"/usr/local/lib/python3.10/dist-packages/keras/src/ops/math.py\", line 59, in segment_sum\n\n  File \"/usr/local/lib/python3.10/dist-packages/keras/src/backend/tensorflow/math.py\", line 17, in segment_sum\n\ndata.shape = [32] does not start with segment_ids.shape = [224]\n\t [[{{node UnsortedSegmentSum_1}}]] [Op:__inference_one_step_on_iterator_16725]"
     ]
    }
   ],
   "source": [
    "# Step 5: Train the Model with Early Stopping\n",
    "early_stopping = EarlyStopping(monitor='val_loss', patience=5, restore_best_weights=True)\n",
    "history = model.fit(train_gen, validation_data=(X_test, y_test), epochs=30, callbacks=[early_stopping])"
   ]
  },
  {
   "cell_type": "code",
   "execution_count": null,
   "id": "f6c0f43c",
   "metadata": {},
   "outputs": [],
   "source": [
    "\n",
    "import numpy as np\n",
    "from sklearn.metrics import confusion_matrix, ConfusionMatrixDisplay\n",
    "import random\n",
    "\n",
    "# Assuming model and data are loaded correctly\n",
    "# Get 10 random samples for prediction\n",
    "random_samples = random.sample(range(len(X_test)), 10)\n",
    "X_random = X_test[random_samples]\n",
    "y_true = y_test[random_samples]\n",
    "\n",
    "# Make predictions\n",
    "y_pred = model.predict(X_random)\n",
    "y_pred_labels = np.argmax(y_pred, axis=1)\n",
    "y_true_labels = np.argmax(y_true, axis=1)\n",
    "\n",
    "# Print true vs predicted values\n",
    "for i, (true_label, pred_label) in enumerate(zip(y_true_labels, y_pred_labels)):\n",
    "    print(f\"Sample {i + 1} - True Label: {true_label}, Predicted Label: {pred_label}\")\n",
    "\n",
    "# Plot confusion matrix\n",
    "y_test_labels = np.argmax(y_test, axis=1)\n",
    "y_pred_test_labels = np.argmax(model.predict(X_test), axis=1)\n",
    "cm = confusion_matrix(y_test_labels, y_pred_test_labels)\n",
    "ConfusionMatrixDisplay(cm).plot(cmap=\"Blues\")\n",
    "plt.show()\n"
   ]
  }
 ],
 "metadata": {
  "colab": {
   "provenance": []
  },
  "kernelspec": {
   "display_name": "Python 3",
   "name": "python3"
  },
  "language_info": {
   "name": "python"
  }
 },
 "nbformat": 4,
 "nbformat_minor": 0
}
